<?xml version="1.0" encoding="UTF-8"?>
<testng-results skipped="0" failed="1" total="2" passed="1">
  <reporter-output>
  </reporter-output>
  <suite name="UnitTests" duration-ms="20" started-at="2017-11-20T11:13:36Z" finished-at="2017-11-20T11:13:36Z">
    <groups>
    </groups>
    <test name="unit" duration-ms="20" started-at="2017-11-20T11:13:36Z" finished-at="2017-11-20T11:13:36Z">
      <class name="LogicTests">
        <test-method status="FAIL" signature="printLogicFailingTest()[pri:0, instance:LogicTests@234bef66]" name="printLogicFailingTest" duration-ms="8" started-at="2017-11-20T14:13:36Z" finished-at="2017-11-20T14:13:36Z">
          <exception class="java.lang.AssertionError">
            <message>
              <![CDATA[expected [not logic text] but found [logic text]]]>
            </message>
            <full-stacktrace>
              <![CDATA[java.lang.AssertionError: expected [not logic text] but found [logic text]
	at org.testng.Assert.fail(Assert.java:94)
	at org.testng.Assert.failNotEquals(Assert.java:494)
	at org.testng.Assert.assertEquals(Assert.java:123)
	at org.testng.Assert.assertEquals(Assert.java:176)
	at org.testng.Assert.assertEquals(Assert.java:186)
	at LogicTests.printLogicFailingTest(LogicTests.java:21)
	at sun.reflect.NativeMethodAccessorImpl.invoke0(Native Method)
	at sun.reflect.NativeMethodAccessorImpl.invoke(NativeMethodAccessorImpl.java:62)
	at sun.reflect.DelegatingMethodAccessorImpl.invoke(DelegatingMethodAccessorImpl.java:43)
	at java.lang.reflect.Method.invoke(Method.java:498)
	at org.testng.internal.MethodInvocationHelper.invokeMethod(MethodInvocationHelper.java:80)
	at org.testng.internal.Invoker.invokeMethod(Invoker.java:714)
	at org.testng.internal.Invoker.invokeTestMethod(Invoker.java:901)
	at org.testng.internal.Invoker.invokeTestMethods(Invoker.java:1231)
	at org.testng.internal.TestMethodWorker.invokeTestMethods(TestMethodWorker.java:127)
	at org.testng.internal.TestMethodWorker.run(TestMethodWorker.java:111)
	at org.testng.TestRunner.privateRun(TestRunner.java:767)
	at org.testng.TestRunner.run(TestRunner.java:617)
	at org.testng.SuiteRunner.runTest(SuiteRunner.java:334)
	at org.testng.SuiteRunner.runSequentially(SuiteRunner.java:329)
	at org.testng.SuiteRunner.privateRun(SuiteRunner.java:291)
	at org.testng.SuiteRunner.run(SuiteRunner.java:240)
	at org.testng.SuiteRunnerWorker.runSuite(SuiteRunnerWorker.java:52)
	at org.testng.SuiteRunnerWorker.run(SuiteRunnerWorker.java:86)
	at org.testng.TestNG.runSuitesSequentially(TestNG.java:1198)
	at org.testng.TestNG.runSuitesLocally(TestNG.java:1123)
	at org.testng.TestNG.run(TestNG.java:1031)
	at org.testng.remote.AbstractRemoteTestNG.run(AbstractRemoteTestNG.java:132)
	at org.testng.remote.RemoteTestNG.initAndRun(RemoteTestNG.java:230)
	at org.testng.remote.RemoteTestNG.main(RemoteTestNG.java:76)
]]>
            </full-stacktrace>
          </exception> <!-- java.lang.AssertionError -->
          <reporter-output>
          </reporter-output>
        </test-method> <!-- printLogicFailingTest -->
        <test-method status="PASS" signature="printLogicTest()[pri:0, instance:LogicTests@234bef66]" name="printLogicTest" duration-ms="1" started-at="2017-11-20T14:13:36Z" finished-at="2017-11-20T14:13:36Z">
          <reporter-output>
          </reporter-output>
        </test-method> <!-- printLogicTest -->
      </class> <!-- LogicTests -->
    </test> <!-- unit -->
  </suite> <!-- UnitTests -->
</testng-results>
